<?xml version="1.0" ?>
<sdf version='1.11'>
  <model name='Teri_urdf'>

    <plugin
      filename='gz-sim-joint-state-publisher-system' 
      name='gz::sim::systems::JointStatePublisher'>
      <topic>joint_states</topic>
      <joint_name>joint2</joint_name>
      <joint_name>joint3</joint_name>
      <joint_name>joint4</joint_name>
      <joint_name>joint5</joint_name>
      <joint_name>pp2_joint</joint_name>
      <joint_name>pp3_joint</joint_name>
    </plugin>


    <plugin
      filename="gz-sim-joint-position-controller-system"
      name="gz::sim::systems::JointPositionController">
      <joint_name>joint2</joint_name>
      <topic>joint2_move</topic>
      <p_gain>1</p_gain>
      <i_gain>0.1</i_gain>
      <d_gain>0.01</d_gain>
      <i_max>1</i_max>
      <i_min>-1</i_min>
      <cmd_max>1000</cmd_max>
      <cmd_min>-1000</cmd_min>
    </plugin>

    <plugin
      filename="gz-sim-joint-position-controller-system"
      name="gz::sim::systems::JointPositionController">
      <joint_name>joint3</joint_name>
      <topic>joint3_move</topic>
      <p_gain>1</p_gain>
      <i_gain>0.1</i_gain>
      <d_gain>0.01</d_gain>
      <i_max>1</i_max>
      <i_min>-1</i_min>
      <cmd_max>1000</cmd_max>
      <cmd_min>-1000</cmd_min>
    </plugin>

    <plugin
      filename="gz-sim-joint-position-controller-system"
      name="gz::sim::systems::JointPositionController">
      <joint_name>joint4</joint_name>
      <topic>joint4_move</topic>
      <p_gain>1</p_gain>
      <i_gain>0.1</i_gain>
      <d_gain>0.01</d_gain>
      <i_max>1</i_max>
      <i_min>-1</i_min>
      <cmd_max>1000</cmd_max>
      <cmd_min>-1000</cmd_min>
    </plugin>

    <plugin
      filename="gz-sim-joint-position-controller-system"
      name="gz::sim::systems::JointPositionController">
      <joint_name>joint5</joint_name>
      <topic>joint5_move</topic>
      <p_gain>1</p_gain>
      <i_gain>0.1</i_gain>
      <d_gain>0.01</d_gain>
      <i_max>1</i_max>
      <i_min>-1</i_min>
      <cmd_max>1000</cmd_max>
      <cmd_min>-1000</cmd_min>
    </plugin>


    <plugin
      filename="gz-sim-thruster-system"
      name="gz::sim::systems::Thruster">
      <use_angvel_cmd>0</use_angvel_cmd>
      <joint_name>pp2_joint</joint_name> 
      <thrust_coefficient>0.004422</thrust_coefficient>
      <fluid_density>1000</fluid_density>
      <propeller_diameter>0.2</propeller_diameter>
    </plugin>

    <plugin
      filename="gz-sim-thruster-system"
      name="gz::sim::systems::Thruster">
      <use_angvel_cmd>0</use_angvel_cmd>
      <joint_name>pp3_joint</joint_name> 
      <thrust_coefficient>0.004422</thrust_coefficient>
      <fluid_density>1000</fluid_density>
      <propeller_diameter>0.2</propeller_diameter>
    </plugin>

    <plugin
      filename="gz-sim-thruster-system"
      name="gz::sim::systems::Thruster">
      <use_angvel_cmd>0</use_angvel_cmd>
      <joint_name>pp4_joint</joint_name> 
      <thrust_coefficient>-0.004422</thrust_coefficient>
      <fluid_density>1000</fluid_density>
      <propeller_diameter>0.2</propeller_diameter>
    </plugin>

    <plugin
      filename="gz-sim-thruster-system"
      name="gz::sim::systems::Thruster">
      <use_angvel_cmd>0</use_angvel_cmd>
      <joint_name>pp5_joint</joint_name> 
      <thrust_coefficient>-0.004422</thrust_coefficient>
      <fluid_density>1000</fluid_density>
      <propeller_diameter>0.2</propeller_diameter>
    </plugin>

    <plugin
      filename="gz-sim-thruster-system"
      name="gz::sim::systems::Thruster">
      <use_angvel_cmd>0</use_angvel_cmd>
      <joint_name>ppt1_joint</joint_name> 
      <thrust_coefficient>0.03</thrust_coefficient>
      <fluid_density>1000</fluid_density>
      <propeller_diameter>0.2</propeller_diameter>
    </plugin>

    <plugin
      filename="gz-sim-thruster-system"
      name="gz::sim::systems::Thruster">
      <use_angvel_cmd>0</use_angvel_cmd>
      <joint_name>ppt2_joint</joint_name> 
      <thrust_coefficient>-0.03</thrust_coefficient>
      <fluid_density>1000</fluid_density>
      <propeller_diameter>0.2</propeller_diameter>
    </plugin>

    <plugin
      filename="gz-sim-hydrodynamics-system"
      name="gz::sim::systems::Hydrodynamics">
      <link_name>base_footprint</link_name>
        <xDotU>-0.02</xDotU>
        <yDotV>-0.1</yDotV>
        <zDotW>-0.05</zDotW>
        <kDotP>0</kDotP>
        <mDotQ>-0.02</mDotQ>
        <nDotR>-0.02</nDotR>
        <xUabsU>-0.5</xUabsU>
        <xU>-2</xU>
        <yVabsV>-5.0</yVabsV>
        <yV>-3</yV>
        <zWabsW>-1.0</zWabsW>
        <zW>-2</zW>
        <kPabsP>-0.001</kPabsP>
        <kP>-0.5</kP>
        <mQabsQ>-0.05</mQabsQ>
        <mQ>-0.5</mQ>
        <nRabsR>-0.05</nRabsR>
        <nR>-0.5</nR>
    </plugin>

    <plugin name="gz::sim::systems::DiffDrive" filename="libignition-gazebo-diff-drive-system.so">
    <left_joint>pp2_joint</left_joint>
    <right_joint>pp3_joint</right_joint>
    <wheel_separation>0.5</wheel_separation> 
    <wheel_radius>0.1</wheel_radius> 
    <odom_publish_frequency>50</odom_publish_frequency>
    <topic>cmd_vel</topic>
    <odom_topic>odom</odom_topic>
    <tf_topic>/tf</tf_topic>
    <frame_id>odom</frame_id>
    <robot_base_frame>base_footprint</robot_base_frame>
    <child_frame_id>base_footprint</child_frame_id>

    </plugin>

    <link name='base_footprint'>
      <pose>-0.0027788000000000001 -0.00052517000000000004 -0.12344 0 0 0</pose>

      <inertial>
        <pose>0 0 -0.028 0 0 0</pose>
        <mass>8.321</mass> 
        <inertia>
          <ixx>0.05018</ixx>
          <ixy>9.2735000000000096e-08</ixy>
          <ixz>-8.1562000000000084e-07</ixz>
          <iyy>0.05018</iyy>
          <iyz>-2.4718999999999918e-07</iyz>
          <izz>0.00956</izz>
        </inertia>
      </inertial>
      
      <collision name='base_link_collision'>
        <pose>0 0 0 0 0 0</pose>
        <geometry>
          <mesh>
            <scale>1 1 1</scale>
            <uri>model://Teri_bot/meshes/visual/base_link.STL</uri>
          </mesh>
        </geometry>
      </collision>
      
      <visual name='base_footprint_visual'>
        <pose>0 0 0 0 0 0</pose>
        <geometry>
          <box>
            <size>0.001 0.001 0.001</size>
          </box>
        </geometry>
      </visual>
      <visual name='base_footprint_fixed_joint_lump__base_link_visual_1'>
        <pose>0 0 0.001 0 0 0</pose>
        <geometry>
          <mesh>
            <scale>1 1 1</scale>
            <uri>model://Teri_bot/meshes/visual/base_link.STL</uri>
          </mesh>
        </geometry>
        <material>
          <diffuse>0.25 0.4375 0.625 1</diffuse>
          <ambient>0.25 0.4375 0.625 1</ambient>
        </material>
      </visual> 

      <sensor name='lidar' type='gpu_lidar'>
        <pose relative_to='base_footprint'>0 0 0.29 0 -1.5708 3.14159</pose>
        <gz_frame_id>lidar_base</gz_frame_id>
        <topic>scan</topic>
        <update_rate>10</update_rate>
        <ray>
          <scan>
              <horizontal>
                  <samples>640</samples>
                  <resolution>1</resolution>
                  <min_angle>-2.4</min_angle>
                  <max_angle>2.4</max_angle>
              </horizontal>
              <vertical>
                  <samples>1</samples>
                  <resolution>1</resolution>
                  <min_angle>-0</min_angle>
                  <max_angle>0</max_angle>
              </vertical>
          </scan>
          <range>
              <min>0.08</min>
              <max>100.0</max>
              <resolution>0.01</resolution>
          </range>
          
        </ray>
        <always_on>1</always_on>
        <visualize>true</visualize>
      </sensor>

      <sensor name="camera" type="boundingbox_camera">
          <pose relative_to='base_footprint'>0 0 0.29 0 -1.5708 3.1416</pose>
          <topic>camera1</topic>
          <camera>
            <horizontal_fov>1.047</horizontal_fov>
            <image>
              <width>1000</width>
              <height>600</height>
            </image>
            <clip>
              <near>0.01</near>
              <far>10</far>
            </clip>
          </camera>
          <always_on>1</always_on>
          <update_rate>30</update_rate>
          <visualize>true</visualize>
      </sensor> 

    </link>

<link name='box'>
  <pose relative_to='base_footprint'>-0.07 0 0.13 0 0 0</pose>
  <inertial>
    <pose>0 0 0 0 0 0</pose>
    <mass>1.2</mass>
    <inertia>
      <ixx>0.01</ixx>
      <ixy>0</ixy>
      <ixz>0</ixz>
      <iyy>0.01</iyy>
      <iyz>0</iyz>
      <izz>0.01</izz>
    </inertia>
  </inertial>

  <collision name='box_collision'>
    <pose relative_to='base_footprint'>-0.07 0 0.13 0 0 0</pose>
    <geometry>
      <box>
        <size> 0.01 0.2 0.15 </size>
      </box>
    </geometry>
  </collision>
</link>

<joint name='box_joint' type='fixed'>
  <parent>base_footprint</parent>
  <child>box</child>
</joint>
    <link name='ppt1'>
      <pose relative_to='base_footprint'>0 0 0.24 1.5708 0 0</pose> 
      <inertial>
        <pose>0 0 0 0 0 0</pose>
        <mass>0.1</mass> 
        <inertia>
          <ixx>0.0001</ixx>
          <ixy>0</ixy>
          <ixz>0</ixz>
          <iyy>0.0001</iyy>
          <iyz>0</iyz>
          <izz>0.0001</izz>
        </inertia>
      </inertial>
      <collision name='ppt1_collision'>
        <pose>0 0 0 0 0 0</pose>
        <geometry>
          <cylinder>
            <radius>0.005</radius> 
            <length>0.001</length> 
          </cylinder>
        </geometry>
      </collision>
    </link>
    <joint name='ppt1_joint' type='revolute'>
      <pose relative_to='base_footprint'>0 0 0.24 1.5708 0 0</pose>
      <parent>base_footprint</parent> 
      <child>ppt1</child>
      <axis>
        <xyz>0 0 1</xyz> 
        <limit>
          <lower>-3.14159</lower>
          <upper>3.14159</upper>
          <effort>0</effort>
          <velocity>0</velocity>
        </limit>
        <dynamics>
          <damping>0.01</damping>
          <friction>0.01</friction>
        </dynamics>
      </axis>
    </joint>

    <link name='ppt2'>
      <pose relative_to='base_footprint'>0 0 0.01 -1.5708 0 0</pose> 
      <inertial>
        <pose>0 0 0 0 0 0</pose>
        <mass>0.1</mass> 
        <inertia>
          <ixx>0.0001</ixx>
          <ixy>0</ixy>
          <ixz>0</ixz>
          <iyy>0.0001</iyy>
          <iyz>0</iyz>
          <izz>0.0001</izz>
        </inertia>
      </inertial>
      <collision name='ppt2_collision'>
        <pose>0 0 0 0 0 0</pose>
        <geometry>
          <cylinder>
            <radius>0.005</radius> 
            <length>0.001</length> 
          </cylinder>
        </geometry>
      </collision>
    </link>
    <joint name='ppt2_joint' type='revolute'>
      <pose relative_to='base_footprint'>0 0 0.01 -1.5708 0 0</pose>
      <parent>base_footprint</parent> 
      <child>ppt2</child>
      <axis>
        <xyz>0 0 1</xyz> 
        <limit>
          <lower>-3.14159</lower>
          <upper>3.14159</upper>
          <effort>0</effort>
          <velocity>0</velocity>
        </limit>
        <dynamics>
          <damping>0.01</damping>
          <friction>0.01</friction>
        </dynamics>
      </axis>
    </joint>


    <joint name='joint2' type='revolute'>
      <pose relative_to='base_footprint'>0.00020000000000000001 -0.09282 0.046695 1.7453000000000001 0 0</pose>
      <parent>base_footprint</parent>
      <child>link2</child>
      <axis>
        <xyz>0 0 1</xyz>
        <limit>
          <lower>-2.3561999999999999</lower>
          <upper>2.3561999999999999</upper>
          <effort>8</effort>
          <velocity>5</velocity>
        </limit>
        <dynamics>
          <spring_reference>0</spring_reference>
          <spring_stiffness>0</spring_stiffness>
        </dynamics>
      </axis>
    </joint>
    <link name='link2'>
      <pose relative_to='joint2'>0 0 0 0 0 0</pose>
      <inertial>
        <pose>-1.8259999999999999e-09 -0.030242999999999999 0.031123999999999999 0 0 0</pose>
        <mass>0.515429</mass>
        <inertia>
          <ixx>8.1651999999999997e-05</ixx>
          <ixy>-9.4838000000000004e-12</ixy>
          <ixz>-1.4407e-08</ixz>
          <iyy>2.4587e-05</iyy>
          <iyz>-8.6957000000000002e-08</iyz>
          <izz>6.1020999999999997e-05</izz>
        </inertia>
      </inertial>
      <collision name='link2_collision'>
        <pose>0 0 0 0 0 0</pose>
        <geometry>
          <mesh>
            <scale>1 1 1</scale>
            <uri>model://Teri_bot/meshes/visual/link2.STL</uri>
          </mesh>
        </geometry>
      </collision>
      <visual name='link2_visual'>
        <pose>0 0 0 0 0 0</pose>
        <geometry>
          <mesh>
            <scale>1 1 1</scale>
            <uri>model://Teri_bot/meshes/visual/link2.STL</uri>
          </mesh>
        </geometry>
        <material>
          <diffuse>0.287499994 0.75000006 0.75000006 1</diffuse>
          <ambient>0.287499994 0.75000006 0.75000006 1</ambient>
        </material>
      </visual>
    </link>

    <link name='pp2'>
      <pose relative_to='base_footprint'>0 -0.129 0.035 0 0 0</pose> 
      <inertial>
        <pose>0 0 0 0 0 0</pose>
        <mass>0.01</mass> 
        <inertia>
          <ixx>0.0001</ixx>
          <ixy>0</ixy>
          <ixz>0</ixz>
          <iyy>0.0001</iyy>
          <iyz>0</iyz>
          <izz>0.0001</izz>
        </inertia>
      </inertial>
      <collision name='pp2_collision'>
        <pose>0 0 0 0 0 0</pose>
        <geometry>
          <cylinder>
            <radius>0.005</radius> 
            <length>0.001</length> 
          </cylinder>
        </geometry>
      </collision>
    </link>
    <joint name='pp2_joint' type='revolute'>
      <pose relative_to='base_footprint'>0 -0.129 0.035 0 0 0</pose>
      <parent>base_footprint</parent> 
      <child>pp2</child>
      <axis>
        <xyz>0 0 1</xyz> 
        <limit>
          <lower>-3.14159</lower>
          <upper>3.14159</upper>
          <effort>0</effort>
          <velocity>0</velocity>
        </limit>
        <dynamics>
          <damping>0.01</damping>
          <friction>0.01</friction>
        </dynamics>
      </axis>
    </joint>


    <joint name='joint3' type='revolute'>
      <pose relative_to='base_footprint'>0.00020000000000000001 -0.087349999999999997 0.22822999999999999 0.7854000000000001 0 0</pose>
      <parent>base_footprint</parent>
      <child>link3</child>
      <axis>
        <xyz>0 0 1</xyz>
        <limit>
          <lower>-2.3561999999999999</lower>
          <upper>2.3561999999999999</upper>
          <effort>8</effort>
          <velocity>5</velocity> 
        </limit>
        <dynamics>
          <spring_reference>0</spring_reference>
          <spring_stiffness>0</spring_stiffness>
        </dynamics>
      </axis>
    </joint>

    <link name='link3'>
      <pose relative_to='joint3'>0 0 0 0 0 0</pose>
      <inertial>
        <pose>-1.8259999999999999e-09 -0.030242999999999999 0.031123999999999999 0 0 0</pose>
        <mass>0.534571</mass>
        <inertia>
          <ixx>8.1651999999999997e-05</ixx>
          <ixy>-9.4838000000000004e-12</ixy>
          <ixz>-1.4407e-08</ixz>
          <iyy>2.4587e-05</iyy>
          <iyz>-8.6957000000000002e-08</iyz>
          <izz>6.1020999999999997e-05</izz>
        </inertia>
      </inertial>
      <collision name='link3_collision'>
        <pose>0 0 0 0 0 0</pose>
        <geometry>
          <mesh>
            <scale>1 1 1</scale>
            <uri>model://Teri_bot/meshes/visual/link3.STL</uri>
          </mesh>
        </geometry>
      </collision>
      <visual name='link3_visual'>
        <pose>0 0 0 0 0 0</pose>
        <geometry>
          <mesh>
            <scale>1 1 1</scale>
            <uri>model://Teri_bot/meshes/visual/link3.STL</uri>
          </mesh>
        </geometry>
        <material>
          <diffuse>0.287499994 0.75000006 0.75000006 1</diffuse>
          <ambient>0.287499994 0.75000006 0.75000006 1</ambient>
        </material>
      </visual>
    </link>

    <link name='pp3'>
      <pose relative_to='base_footprint'>0 -0.129 0.247 0 0 0</pose> 
      <inertial>
        <pose>0 0 0 0 0 0</pose>
        <mass>0.01</mass> 
        <inertia>
          <ixx>0.0001</ixx>
          <ixy>0</ixy>
          <ixz>0</ixz>
          <iyy>0.0001</iyy>
          <iyz>0</iyz>
          <izz>0.0001</izz>
        </inertia>
      </inertial>
      <collision name='pp3_collision'>
        <pose>0 0 0 0 0 0</pose>
        <geometry>
          <cylinder>
            <radius>0.005</radius> 
            <length>0.001</length> 
          </cylinder>
        </geometry>
      </collision>
    </link>
    <joint name='pp3_joint' type='revolute'>
      <pose relative_to='base_footprint'>0 -0.129 0.247 0 0 0</pose>
      <parent>base_footprint</parent> 
      <child>pp3</child>
      <axis>
        <xyz>0 0 1</xyz> 
        <limit>
          <lower>-3.14159</lower>
          <upper>3.14159</upper>
          <effort>0</effort>
          <velocity>0</velocity>
        </limit>
        <dynamics>
          <damping>0.01</damping>
          <friction>0.01</friction>
        </dynamics>
      </axis>
    </joint>

    <joint name='joint4' type='revolute'>
      <pose relative_to='base_footprint'>0.00020000000000000001 0.087349999999999997 0.22822999999999999 -0.7854000000000001 0 0</pose>
      <parent>base_footprint</parent>
      <child>link4</child>
      <axis>
        <xyz>0 0 1</xyz>
        <limit>
          <lower>-2.3561999999999999</lower>
          <upper>2.3561999999999999</upper>
          <effort>8</effort>
          <velocity>5</velocity> 
        </limit>
        <dynamics>
          <spring_reference>0</spring_reference>
          <spring_stiffness>0</spring_stiffness>
        </dynamics>
      </axis>
    </joint>
    <link name='link4'>
      <pose relative_to='joint4'>0 0 0 0 0 0</pose>
      <inertial>
        <pose>1.8259999999999999e-09 0.030242999999999999 0.031123999999999999 0 0 0</pose>
        <mass>0.534571</mass>
        <inertia>
          <ixx>8.1651999999999997e-05</ixx>
          <ixy>-9.4838000000000004e-12</ixy>
          <ixz>1.4407e-08</ixz>
          <iyy>2.4587e-05</iyy>
          <iyz>8.6957000000000002e-08</iyz>
          <izz>6.1020999999999997e-05</izz>
        </inertia>
      </inertial>
      <collision name='link4_collision'>
        <pose>0 0 0 0 0 0</pose>
        <geometry>
          <mesh>
            <scale>1 1 1</scale>
            <uri>model://Teri_bot/meshes/visual/link4.STL</uri>
          </mesh>
        </geometry>
      </collision>
      <visual name='link4_visual'>
        <pose>0 0 0 0 0 0</pose>
        <geometry>
          <mesh>
            <scale>1 1 1</scale>
            <uri>model://Teri_bot/meshes/visual/link4.STL</uri>
          </mesh>
        </geometry>
        <material>
          <diffuse>0.287499994 0.75000006 0.75000006 1</diffuse>
          <ambient>0.287499994 0.75000006 0.75000006 1</ambient>
        </material>
      </visual>
    </link>

    <link name='pp4'>
      <pose relative_to='base_footprint'>0 0.129 0.247 0 0 0</pose> 
      <inertial>
        <pose>0 0 0 0 0 0</pose>
        <mass>0.01</mass> 
        <inertia>
          <ixx>0.0001</ixx>
          <ixy>0</ixy>
          <ixz>0</ixz>
          <iyy>0.0001</iyy>
          <iyz>0</iyz>
          <izz>0.0001</izz>
        </inertia>
      </inertial>
      <collision name='pp4_collision'>
        <pose>0 0 0 0 0 0</pose>
        <geometry>
          <cylinder>
            <radius>0.005</radius> 
            <length>0.001</length> 
          </cylinder>
        </geometry>
      </collision>
    </link>
    <joint name='pp4_joint' type='revolute'>
      <pose relative_to='base_footprint'>0 0.129 0.247 0 0 0</pose>
      <parent>base_footprint</parent> 
      <child>pp4</child>
      <axis>
        <xyz>0 0 1</xyz> 
        <limit>
          <lower>-3.14159</lower>
          <upper>3.14159</upper>
          <effort>0</effort>
          <velocity>0</velocity>
        </limit>
        <dynamics>
          <damping>0.01</damping>
          <friction>0.01</friction>
        </dynamics>
      </axis>
    </joint>

    <joint name='joint5' type='revolute'>
      <pose relative_to='base_footprint'>0.00020000000000000001 0.09282 0.046695 -1.7453000000000001 0 0</pose>
      <parent>base_footprint</parent>
      <child>link5</child>
      <axis>
        <xyz>0 0 1</xyz>
        <limit>
          <lower>-2.3561999999999999</lower>
          <upper>2.3561999999999999</upper>
          <effort>8</effort>
          <velocity>5</velocity> 
        </limit>
        <dynamics>
          <spring_reference>0</spring_reference>
          <spring_stiffness>0</spring_stiffness>
        </dynamics>
      </axis>
    </joint>
    <link name='link5'>
      <pose relative_to='joint5'>0 0 0 0 0 0</pose>
      <inertial>
        <pose>1.8259999999999999e-09 0.030242999999999999 0.031123999999999999 0 0 0</pose>
        <mass>0.515429</mass>
        <inertia>
          <ixx>8.1651999999999997e-05</ixx>
          <ixy>-9.4838000000000004e-12</ixy>
          <ixz>1.4407e-08</ixz>
          <iyy>2.4587e-05</iyy>
          <iyz>8.6957000000000002e-08</iyz>
          <izz>6.1020999999999997e-05</izz>
        </inertia>
      </inertial>
      <collision name='link5_collision'>
        <pose>0 0 0 0 0 0</pose>
        <geometry>
          <mesh>
            <scale>1 1 1</scale>
            <uri>model://Teri_bot/meshes/visual/link5.STL</uri>
          </mesh>
        </geometry>
      </collision>
      <visual name='link5_visual'>
        <pose>0 0 0 0 0 0</pose>
        <geometry>
          <mesh>
            <scale>1 1 1</scale>
            <uri>model://Teri_bot/meshes/visual/link5.STL</uri>
          </mesh>
        </geometry>
        <material>
          <diffuse>0.287499994 0.75000006 0.75000006 1</diffuse>
          <ambient>0.287499994 0.75000006 0.75000006 1</ambient>
        </material>
      </visual>
    </link>

    <link name='pp5'>
      <pose relative_to='base_footprint'>0 0.129 0.035 0 0 0</pose> 
      <inertial>
        <pose>0 0 0 0 0 0</pose>
        <mass>0.01</mass> 
        <inertia>
          <ixx>0.0001</ixx>
          <ixy>0</ixy>
          <ixz>0</ixz>
          <iyy>0.0001</iyy>
          <iyz>0</iyz>
          <izz>0.0001</izz>
        </inertia>
      </inertial>
      <collision name='pp5_collision'>
        <pose>0 0 0 0 0 0</pose>
        <geometry>
          <cylinder>
            <radius>0.005</radius> 
            <length>0.001</length> 
          </cylinder>
        </geometry>
      </collision>
    </link>
    <joint name='pp5_joint' type='revolute'>
      <pose relative_to='base_footprint'>0 0.129 0.035 0 0 0</pose>
      <parent>base_footprint</parent> 
      <child>pp5</child>
      <axis>
        <xyz>0 0 1</xyz> 
        <limit>
          <lower>-3.14159</lower>
          <upper>3.14159</upper>
          <effort>0</effort>
          <velocity>0</velocity>
        </limit>
        <dynamics>
          <damping>0.01</damping>
          <friction>0.01</friction>
        </dynamics>
      </axis>
    </joint>

    <frame name='base_footprint_joint' attached_to='base_footprint'>
      <pose>0 0 0.001 0 0 0</pose>
    </frame>
    <frame name='base_link' attached_to='base_footprint_joint'>
      <pose>0 0 0 0 0 0</pose>
    </frame>
  </model>
</sdf>
